Workbook
Name PICUAT: #REF!
Name SDefect: [1]Lookup!$G$1:$G$9
Name Severity: [1]Lookup!$F$1:$F$6

Sheet MAPPING MD & SKENARIO
A1: No | B1: Proses | C1: Average Testing (Hours) | D1: Buffer Waktu Testing (*30%) | G1: No | H1: Kode Skenario | I1: PIC UAT | J1: E-mail MUF
A2: 1 | B2: Web View BSI OTO | C2: 1 | D2: =C2+(C2*30%) -> 1.3 | G2: 1 | H2: BYD001 | I2: Azhar | J2: azhar.azhar@muf.co.id
A3: 2 | B3: CBAS Digital | C3: 1.5 | D3: =C3+(C3*30%) -> 1.95 | G3: 2 | H3: BYD002 | I3: Affinia | J3: affinia.by@muf.co.id
A4: 3 | B4: Email Notifikasi Submit Order | C4: 0.2 | D4: =C4+(C4*30%) -> 0.26 | G4: 3 | H4: BYD003 | I4: Kevin | J4: kevin.hardianus@muf.co.id
A5: 4 | B5: Entry Form Digital | C5: 1 | D5: =C5+(C5*30%) -> 1.3 | G5: 4 | H5: BYD004 | I5: Rasya | J5: rasya.raharjo@muf.co.id
A6: 5 | B6: Data Entry - Screening 2 | C6: 2 | D6: =C6+(C6*30%) -> 2.6 | G6: 5 | H6: BYD005 | I6: Azhar | J6: azhar.azhar@muf.co.id
A7: 6 | B7: Reguler Survey | C7: 1 | D7: =C7+(C7*30%) -> 1.3 | G7: 6 | H7: BYD006 | I7: Affinia | J7: affinia.by@muf.co.id
A8: 7 | B8: Credit Approval (CA) | C8: 2 | D8: =C8+(C8*30%) -> 2.6 | G8: 7 | H8: BYD007 | I8: Kevin | J8: kevin.hardianus@muf.co.id
A9: 8 | B9: Tele Survey | C9: 1 | D9: =C9+(C9*30%) -> 1.3 | G9: 8 | H9: BYD008 | I9: Rasya | J9: rasya.raharjo@muf.co.id
A10: 9 | B10: KYC | C10: 1 | D10: =C10+(C10*30%) -> 1.3 | G10: 9 | H10: BYD009 | I10: Azhar | J10: azhar.azhar@muf.co.id
A11: 10 | B11: PO/CL | C11: 0.5 | D11: =C11+(C11*30%) -> 0.65 | G11: 10 | H11: BYD010 | I11: Affinia | J11: affinia.by@muf.co.id
A12: 11 | B12: FDE | C12: 2 | D12: =C12+(C12*30%) -> 2.6 | G12: 11 | H12: BYD011 | I12: Kevin | J12: kevin.hardianus@muf.co.id
A13: 12 | B13: Verifikasi Data-PPD | C13: 1.5 | D13: =C13+(C13*30%) -> 1.95 | G13: 12 | H13: BYD012 | I13: Rasya | J13: rasya.raharjo@muf.co.id
... A24: 23 | B24: Parameter CBAS | C24: 0.3 | D24: =C24+(C24*30%) -> 0.39 | G24: 23 | H24: BYD023 | I24: Kevin | J24: kevin.hardianus@muf.co.id
G25: 24 | H25: BYD024 | I25: Rasya | J25: rasya.raharjo@muf.co.id
G26: 25 | H26: BYD025 | I26: Azhar | J26: azhar.azhar@muf.co.id
G27: 26 | H27: BYD026 | I27: Affinia | J27: affinia.by@muf.co.id
G28: 27 | H28: BYD027 | I28: Kevin | J28: kevin.hardianus@muf.co.id
G29: 28 | H29: BYD028 | I29: Rasya | J29: rasya.raharjo@muf.co.id
G30: 29 | H30: BYD029 | I30: Azhar | J30: azhar.azhar@muf.co.id
G31: 30 | H31: BYD030 | I31: Affinia | J31: affinia.by@muf.co.id
G32: 31 | H32: BYD031 | I32: Kevin | J32: kevin.hardianus@muf.co.id
G33: 32 | H33: BYD032 | I33: Rasya | J33: rasya.raharjo@muf.co.id
G34: 33 | H34: BYD033 | I34: Azhar | J34: azhar.azhar@muf.co.id
G35: 34 | H35: BYD034 | I35: Affinia | J35: affinia.by@muf.co.id
G36: 35 | H36: BYD035 | I36: Kevin | J36: kevin.hardianus@muf.co.id | M36: x
G37: 36 | H37: BYD036 | I37: Rasya | J37: rasya.raharjo@muf.co.id
G38: 37 | H38: BYD037 | I38: Azhar | J38: azhar.azhar@muf.co.id
G39: 38 | H39: BYD038 | I39: Affinia | J39: affinia.by@muf.co.id
G40: 39 | H40: BYD039 | I40: Kevin | J40: kevin.hardianus@muf.co.id
G41: 40 | H41: BYD040 | I41: Azhar | J41: azhar.azhar@muf.co.id
G42: 41 | H42: BYD041 | I42: Rasya | J42: rasya.raharjo@muf.co.id

Sheet MATRIX KONTRAK
A1: NEW MATRIX DATA UAT
A3: NO | B3: MATRIX DATA | C3: SOURCE ORDER | D3: TIPE ORDER | E3: TIPE NASABAH | F3: SEGMEN PEKERJAAN | G3: EVENT | H3: CUSTOMER CATEGORY | I3: STATUS PERKAWINAN | J3: JENIS KENDARAAN | K3: WILAYAH | L3: SPK? (Y/N) | M3: Hasil Screening MASS | N3: CBAS DIGITAL | O3: CBAS MASS | P3: KOLEKTIBILITAS NASABAH | S3: MAPPING RAC DBR | V3: FINAL SCREENING | W3: PROSES RTRE | Z3: TANGGAL RTRE | AA3: HASIL CBAS MASS | AC3: PROSES CANCEL/REJECT | AJ3: AUTO REJECT | AM3: VALIDASI ACCEPT OFFER
P4: DEBITUR | Q4: PASANGAN | R4: HASIL MATRIX KOL | S4: PENDAPATAN | T4: DBR | U4: RAC DBR | W4: CREDIT APPROVAL | X4: FDE | Y4: VERDAT | AA4: NEW | AB4: DEDUP | AC4: EFD | AD4: To Do List SC2 | AE4: Tele Survey | AF4: Reguler Survey | AG4: KYC | AH4: Credit Approval | AI4: PO/CL | AJ4: SC1 | AK4: SC2 | AL4: SC3 | AM4: CANCEL OFFER | AN4: EXPIRED OFFER
A5: 1 | B5: BS001 | C5: BSI BYOND | D5: WHITELIST | E5: NEW | F5: ASN | G5: TANPA EVENT | H5: BSI PAYROLL | I5: BELUM KAWIN | J5: MOBIL BARU | K5: JABODETABEK & SERANG | L5: Y | M5: REGULER SURVEY | N5: FOUND | O5: DEDUP | P5: OK | R5: OK | S5: <= 10 juta/bulan | T5: <= 40% | U5: OK | V5: OK
A6: 2 | B6: BS002 | C6: BSI BYOND | D6: WHITELIST | F6: BUMN / BUMD | G6: GAIKINDO INDONESIA INTERNATIONAL AUTO SHOW (GIIAS) | H6: BSI PRIORITAS | I6: KAWIN | J6: MOBIL BARU | K6: SUMATRA | L6: N | M6: INSTANT APPROVAL | P6: OK | Q6: OK | R6: OK | S6: > 10 juta/bulan | T6: <= 50% | U6: OK | V6: OK | W6: v | Z6: < TGL 15 | AB6: v
A7: 3 | B7: BS003 | C7: BSI BYOND | D7: WHITELIST | E7: AO | F7: Pegawai Swasta | G7: GAIKINDO JAKARTA AUTO WEEK (GJAW) | H7: ELSE | I7: BELUM KAWIN | J7: MOBIL BARU | K7: KALIMANTAN | L7: Y | M7: REGULER SURVEY | N7: DEDUP | O7: FOUND | P7: OK | R7: OK | S7: <= 10 juta/bulan | T7: <= 40% | U7: OK | V7: OK
A8: 4 | B8: BS004 | C8: BSI BYOND | D8: WHITELIST | F8: Profesional | G8: INDONESIA INTERNATIONAL MOTOR SHOW (IIMS) | H8: BSI PAYROLL | I8: KAWIN | J8: MOBIL BEKAS | K8: JABODETABEK & SERANG | L8: N | M8: INSTANT APPROVAL | P8: OK | Q8: NOT OK | R8: OK | S8: > 10 juta/bulan | T8: <= 50% | U8: OK | V8: OK
A9: 5 | B9: BS005 | C9: BSI BYOND | D9: WHITELIST | F9: Wiraswasta | G9: BSI INTERNATIONAL EXPO | H9: BSI PRIORITAS | I9: BELUM KAWIN | J9: MOBIL BEKAS | K9: SUMATRA | L9: Y | M9: REGULER SURVEY | P9: OK | R9: OK | S9: <= 10 juta/bulan | T9: <= 40% | U9: OK | V9: OK
A10: 6 | B10: BS006 | C10: BSI BYOND | D10: WHITELIST | E10: RO | F10: Dokter | G10: MUF AUTO FEST | H10: ELSE | I10: KAWIN | J10: MOBIL BEKAS | K10: KALIMANTAN | L10: N | M10: INSTANT APPROVAL | N10: NO RESPONSE | O10: FOUND | P10: OK | Q10: OK | R10: OK | S10: > 10 juta/bulan | T10: <= 50% | U10: OK | V10: ELSE | X10: v | Z10: < TGL 15 | AB10: v
A11: 7 | B11: BS007 | C11: BSI BYOND | D11: WHITELIST | F11: TNI / Polri | G11: BSI OTO SHOW | H11: BSI PAYROLL | I11: BELUM KAWIN | J11: MOTOR BARU | K11: JABODETABEK & SERANG | L11: Y | M11: REGULER SURVEY | P11: OK | R11: OK | S11: <= 10 juta/bulan | T11: <= 40% | U11: OK | V11: OK
A12: 8 | B12: BS008 | C12: BSI BYOND | D12: WHITELIST | F12: Pejabat Penyelenggara Negara | G12: CUSTOMER GATHERING | H12: BSI PRIORITAS | I12: KAWIN | J12: MOTOR BARU | K12: SUMATRA | L12: N | M12: INSTANT APPROVAL | P12: OK | Q12: NOT OK | R12: OK | S12: > 10 juta/bulan | T12: <= 50% | U12: OK | V12: OK
A13: 9 | B13: BS009 | C13: BSI BYOND | D13: WHITELIST | E13: AO | F13: Lainnya | G13: SHOW UNIT & TEST DRIVE BSI OTO | H13: ELSE | I13: BELUM KAWIN | J13: MOTOR BARU | K13: KALIMANTAN | L13: Y | M13: REGULER SURVEY | N13: DEDUP | O13: DEDUP | P13: OK | R13: OK | S13: <= 10 juta/bulan | T13: <= 40% | U13: OK | V13: OK | Y13: v | Z13: > TGL 15 | AA13: v
A14: 10 | B14: BS010 | C14: BSI BYOND | D14: WHITELIST | F14: ASN | G14: MILAD BSI | H14: BSI PAYROLL | I14: KAWIN | J14: MOBIL BARU | K14: JABODETABEK & SERANG | L14: N | M14: INSTANT APPROVAL | P14: OK | Q14: OK | R14: OK | S14: > 10 juta/bulan | T14: <= 50% | U14: OK | V14: OK
A15: 11 | B15: BS011 | C15: BSI BYOND | D15: WHITELIST | E15: NEW | F15: Pegawai Swasta | G15: BSI FEST RAMADHAN | H15: BSI PRIORITAS | I15: BELUM KAWIN | J15: MOBIL BEKAS | K15: SUMATRA | L15: Y | M15: REGULER SURVEY | N15: NO RESPONSE | O15: NO RESPONSE | P15: OK | R15: OK | S15: <= 10 juta/bulan | T15: <= 40% | U15: OK | V15: ELSE
A16: 12 | B16: BS012 | C16: BSI BYOND | D16: NON-WHITELIST | F16: BUMN / BUMD | G16: TANPA EVENT | H16: ELSE | I16: KAWIN | J16: MOBIL BARU | K16: JABODETABEK & SERANG | L16: N | M16: REGULER SURVEY | W16: v
A17: 13 | B17: BS013 | C17: BSI BYOND | D17: NON-WHITELIST | F17: ASN | G17: INDONESIA INTERNATIONAL MOTOR SHOW (IIMS) | H17: BSI PAYROLL | I17: BELUM KAWIN | J17: MOBIL BEKAS | K17: SUMATRA | L17: Y | M17: INSTANT APPROVAL
A18: 14 | B18: BS014 | C18: BSI BYOND | D18: NON-WHITELIST | F18: Pegawai Swasta | G18: BSI INTERNATIONAL EXPO | H18: BSI PRIORITAS | I18: KAWIN | J18: MOTOR BARU | K18: KALIMANTAN | L18: N | M18: REGULER SURVEY | X18: v
A19: 15 | B19: BS015 | C19: BSI BYOND | D19: NON-WHITELIST | F19: Dokter | G19: MUF AUTO FEST | H19: ELSE | I19: BELUM KAWIN | J19: MOBIL BARU | K19: JABODETABEK & SERANG | L19: Y | M19: INSTANT APPROVAL
A20: 16 | B20: BS016 | C20: BSI BYOND | D20: NON-WHITELIST | F20: Pejabat Penyelenggara Negara | G20: BSI OTO SHOW | H20: BSI PAYROLL | I20: KAWIN | J20: MOBIL BEKAS | K20: SUMATRA | L20: N | M20: REGULER SURVEY
A21: 17 | B21: BS017 | C21: BSI BYOND | D21: NON-WHITELIST | F21: TNI / Polri | G21: CUSTOMER GATHERING | H21: BSI PRIORITAS | I21: BELUM KAWIN | J21: MOTOR BARU | K21: KALIMANTAN | L21: Y | M21: INSTANT APPROVAL | Y21: v
A22: 18 | B22: BS018 | C22: BSI BYOND | D22: WHITELIST | I22: BELUM KAWIN | J22: MOBIL BARU | L22: Y | P22: NOT OK | R22: NOT OK | S22: > 10 juta/bulan | T22: <= 50% | U22: OK | V22: NOT OK
A23: 19 | B23: BS019 | C23: BSI BYOND | D23: WHITELIST | I23: KAWIN | J23: MOBIL BEKAS | L23: N | P23: NOT OK | Q23: OK | R23: NOT OK | S23: <= 10 juta/bulan | T23: <= 40% | U23: OK | V23: NOT OK
A24: 20 | B24: BS020 | C24: BSI BYOND | D24: WHITELIST | I24: BELUM KAWIN | J24: MOTOR BARU | L24: Y | P24: NOT OK | Q24: NOT OK | R24: NOT OK | S24: <= 10 juta/bulan | T24: > 40% | U24: NOT OK | V24: NOT OK
A25: 21 | B25: BS021 | C25: BSI BYOND | D25: WHITELIST | I25: KAWIN | J25: MOBIL BARU | L25: N | P25: OK | Q25: NOT OK | R25: OK | S25: <= 10 juta/bulan | T25: > 40% | U25: NOT OK | V25: NOT OK
A26: 22 | B26: BS022 | C26: BSI BYOND | D26: WHITELIST | I26: BELUM KAWIN | J26: MOBIL BEKAS | L26: Y | P26: OK | Q26: OK | R26: OK | S26: > 10 juta/bulan | T26: > 50% | U26: NOT OK | V26: NOT OK
A27: 23 | B27: BS023 | C27: BSI BYOND | D27: WHITELIST | I27: KAWIN | J27: MOTOR BARU | L27: N | P27: OK | Q27: - | R27: OK | S27: <= 10 juta/bulan | T27: > 40% | U27: NOT OK | V27: NOT OK
A28: 24 | B28: BS024 | C28: BSI BYOND | D28: WHITELIST | I28: BELUM KAWIN | J28: MOBIL BARU | L28: Y | P28: OK | Q28: - | R28: OK | S28: > 10 juta/bulan | T28: > 50% | U28: NOT OK | V28: NOT OK
A29: 25 | B29: BS025 | C29: BSI BYOND | D29: WHITELIST | I29: KAWIN | J29: MOBIL BEKAS | L29: N | AC29: v
A30: 26 | B30: BS026 | C30: BSI BYOND | D30: NON-WHITELIST | I30: BELUM KAWIN | J30: MOTOR BARU | L30: Y | AD30: v
A31: 27 | B31: BS027 | C31: BSI BYOND | D31: WHITELIST | I31: KAWIN | J31: MOBIL BARU | L31: N | AE31: v
A32: 28 | B32: BS028 | C32: BSI BYOND | D32: NON-WHITELIST | I32: BELUM KAWIN | J32: MOBIL BEKAS | L32: Y | AF32: v
A33: 29 | B33: BS029 | C33: BSI BYOND | D33: WHITELIST | I33: KAWIN | J33: MOTOR BARU | L33: N | AG33: v
A34: 30 | B34: BS030 | C34: BSI BYOND | D34: NON-WHITELIST | I34: BELUM KAWIN | J34: MOBIL BARU | L34: Y | AH34: v
A35: 31 | B35: BS031 | C35: BSI BYOND | D35: WHITELIST | I35: KAWIN | J35: MOBIL BEKAS | L35: N | AI35: v
A36: 32 | B36: BS032 | C36: BSI BYOND | D36: NON-WHITELIST | I36: BELUM KAWIN | J36: MOTOR BARU | L36: Y | AJ36: v
A37: 33 | B37: BS033 | C37: BSI BYOND | D37: WHITELIST | I37: KAWIN | J37: MOBIL BARU | L37: N | AK37: v
A38: 34 | B38: BS034 | C38: BSI BYOND | D38: NON-WHITELIST | I38: BELUM KAWIN | J38: MOBIL BEKAS | L38: Y | AL38: v
A39: 35 | B39: BS035 | C39: BSI BYOND | D39: WHITELIST | L39: N | M39: REGULER SURVEY | AM39: v
A40: 36 | B40: BS036 | C40: BSI BYOND | D40: WHITELIST | L40: Y | M40: REGULER SURVEY | AN40: v
A41: 37 | B41: BS037 | C41: BSI BYOND | D41: WHITELIST | L41: N | M41: INSTANT APPROVAL | AM41: v
...

Sheet TEST CASES
A1: Leader : Adityo
A2: PIC : Kevin, Azhar, Affinia, Rasya
A3: No | B3: Test Case ID | C3: Test Data | D3: Module/Feature | E3: Test Case Description | F3: Test Steps | G3: Expected Result | H3: PIC | I3: Email | J3: Hours | K3: Retest | L3: Documentation | M3: Total | N3: Total Hours | O3: MD UAT | P3: PIC | Q3: Duration
A4: 1 | B4: BYD001-01 | C4: ='MATRIX KONTRAK'!B5 -> BS001 | D4: Web View BSI OTO | E4: Melakukan pengajuan data kontrak melalui Web View BSI BYOND | F4: 1. Akses menu Web View BSI BYOND 2. Melakukan inputan data kendaraan 3. Melakukan inputan simulasi pembiayaan 4. Melakukan inputan verifikasi data 5. Konfirmasi pengajuan | G4: 1. Berhasil akses menu Web View BSI BYOND 2. Berhasil melakukan inputan data kendaraan 3. Berhasil melakukan inputan simulasi pembiayaan 4. Berhasil melakukan inputan data nasabah 5. Berhasil submit pengajuan dari Web View BSI BYOND | H4: =VLOOKUP(LEFT(B4,FIND("-",B4)-1),'MAPPING MD & SKENARIO'!$H$2:$I$42,2,FALSE) -> Azhar | I4: =VLOOKUP(H4,'MAPPING MD & SKENARIO'!$I$2:$J$42,2,FALSE) -> azhar.azhar@muf.co.id | J4: =VLOOKUP(D4,'MAPPING MD & SKENARIO'!B:D,3,FALSE) -> 1.3 | K4: =J4*50% -> 0.65 | L4: 1 | M4: =ROUNDUP(SUM(J4:L4),0) -> 3 | N4: =ROUNDUP(SUM(M4:M320),0) -> 1132 | O4: =ROUNDUP(N4/6,0) -> 189 | P4: 4 | Q4: =ROUNDUP(O4/P4,0) -> 48
A5: 2 | B5: BYD001-02 | D5: CBAS Digital | E5: Melakukan proses verifikasi administrasi atas pengajuan yang dilakukan sebelumnya | F5: 1. Akses menu CBAS Digital 2. Lakukan pengecekan data yang sudah terhit ke CBAS Digital 3. Cek callback actcode Tracking BSI pada database (Excel Lampiran BSI BYOND - Tracking BSI) | G5: 1. Berhasil akses menu CBAS Digital 2. Hasil screening data pada CBAS Digital untuk Verifikasi Administrasi sudah sesuai 3. Callback actcode sudah sesuai | H5: =VLOOKUP(LEFT(B5,FIND("-",B5)-1),'MAPPING MD & SKENARIO'!$H$2:$I$42,2,FALSE) -> Azhar | I5: =VLOOKUP(H5,'MAPPING MD & SKENARIO'!$I$2:$J$42,2,FALSE) -> azhar.azhar@muf.co.id | J5: =VLOOKUP(D5,'MAPPING MD & SKENARIO'!B:D,3,FALSE) -> 1.95 | K5: =J5*50% -> 0.975 | L5: 1 | M5: =ROUNDUP(SUM(J5:L5),0) -> 4
A6: 3 | B6: BYD001-03 | D6: Email Notifikasi Submit Order | E6: Pengecekan kiriman data dan format email submit order | F6: 1. Buka e-mail 2. Pastikan e-email terkirim 3. Lakukan pengecekan format dan data pada kiriman e-mail | G6: 1. Berhasil akses e-mail 2. E-mail berhasil masuk ke Inbox 3. Format dan data terlampir pada e-mail sudah sesuai | H6: =VLOOKUP(LEFT(B6,FIND("-",B6)-1),'MAPPING MD & SKENARIO'!$H$2:$I$42,2,FALSE) -> Azhar | I6: =VLOOKUP(H6,'MAPPING MD & SKENARIO'!$I$2:$J$42,2,FALSE) -> azhar.azhar@muf.co.id | J6: =VLOOKUP(D6,'MAPPING MD & SKENARIO'!B:D,3,FALSE) -> 0.26 | K6: =J6*50% -> 0.13 | L6: 1 | M6: =ROUNDUP(SUM(J6:L6),0) -> 2
A7: 4 | B7: BYD001-04 | D7: Entry Form Digital | E7: Pengecekan dan lanjutan inputan data kontrak pada EFD MASS | F7: 1. Akses menu EFD 2. Proses lanjutan inputan data 3. Lakukan pengecekan pada mapping submit order data terkait autofill data, penambahan field baru dan penambahan label baru (Excel Lampiran BSI BYOND - Sheet Mapping Submit Order) 4. Konfirmasi EFD 5. Cek callback actcode tracking BSI dan tracking order MASS (Excel Lampiran BSI BYOND - Tracking BSI) | G7: 1. Berhasil akses EFD 2. Berhasil melanjutkan inputan data 3. Terkait autofill, penambahan field dan penambahan label di EFD sudah sesuai 4. Berhasil konfirmasi EFD 5. Callback tracking BSI dan tracking order MASS sesuai | H7: =VLOOKUP(LEFT(B7,FIND("-",B7)-1),'MAPPING MD & SKENARIO'!$H$2:$I$42,2,FALSE) -> Azhar | I7: =VLOOKUP(H7,'MAPPING MD & SKENARIO'!$I$2:$J$42,2,FALSE) -> azhar.azhar@muf.co.id | J7: =VLOOKUP(D7,'MAPPING MD & SKENARIO'!B:D,3,FALSE) -> 1.3 | K7: =J7*50% -> 0.65 | L7: 1 | M7: =ROUNDUP(SUM(J7:L7),0) -> 3
A8: 5 | B8: BYD001-05 | D8: Data Entry - Screening 2 | E8: Pengecekan dan proses lanjutan inputan data kontrak pada SC2 | F8: 1. Akses menu To Do List SC2 2. Pengecekan penambahan informasi tipe order dan customer category pada tampilan data to do list sc2 3. Masuk ke form data entry SC2 4. Melakukan proses inputan data entry serta melakukan pengecekan mapping submit order data terkait autofill data, penambahan field baru dan penambahan label baru (Excel Lampiran BSI BYOND - Sheet Mapping Submit Order) 5. Input struktur kredit sesuai dengan matrix paket kredit (Excel Lampiran BSI BYOND - Sheet Matrix Paket Kredit Mobil Baru/Mobil Bekas/Motor Baru) 6. Konfirmasi data entry screening 2 7. Cek callback actcode tracking BSI dan tracking order MASS (Excel Lampiran BSI BYOND - Tracking BSI) | G8: 1. Berhasil masuk ke menu to do list SC2 2. Tambahan informasi pada tampilan to do list sudah sesuai 3. Berhasil masuk ke form data entry SC2 4. Berhasil menlanjutkan inputan dan autofill, penambahan field serta penambahan label sudah sesuai 5. Inputan struktur kredit sudah sesuai dengan matrix paket kredit 6. Berhasil konfirmasi 7. Callback tracking BSI dan tracking order MASS sesuai | H8: =VLOOKUP(LEFT(B8,FIND("-",B8)-1),'MAPPING MD & SKENARIO'!$H$2:$I$42,2,FALSE) -> Azhar | I8: =VLOOKUP(H8,'MAPPING MD & SKENARIO'!$I$2:$J$42,2,FALSE) -> azhar.azhar@muf.co.id | J8: =VLOOKUP(D8,'MAPPING MD & SKENARIO'!B:D,3,FALSE) -> 2.6 | K8: =J8*50% -> 1.3 | L8: 1 | M8: =ROUNDUP(SUM(J8:L8),0) -> 5
A9: 6 | B9: BYD001-06 | D9: Reguler Survey | E9: Proses actcode terima offer dan lanjutan inputan data kontrak pada Reguler Survey | F9: 1. Akses menu Reguler Survey 2. Cek validasi ketika BSI BYOND belum accept offer 3. Lakukan proses accept offer 4. Akses form Reguler Survey 5. Klik button Detail Application pada Reguler Survey dan lakukan pengecekan informasi data pada Tab Order Digital 6. Lanjutan proses inputan data pada Reguler Survey 7. Konfirmasi Reguler Survey 8. Cek callback actcode tracking BSI dan tracking order MASS (Excel Lampiran BSI BYOND - Tracking BSI) | G9: 1. Berhasil masuk ke menu Reguler Survey 2. Validasi belum accept offer sudah sesuai 3. Berhasil proses accept offer 4. Berhasil masuk ke form Reguler Survey 5. Berhasil klik button Detail Application dan informasi pada Tab Order Digital sudah sesuai 6. Berhasil input Reguler Survey 7. Berhasil konfirmasi Reguler Survey 8. Callback tracking BSI dan tracking order MASS sesuai | H9: =VLOOKUP(LEFT(B9,FIND("-",B9)-1),'MAPPING MD & SKENARIO'!$H$2:$I$42,2,FALSE) -> Azhar | I9: =VLOOKUP(H9,'MAPPING MD & SKENARIO'!$I$2:$J$42,2,FALSE) -> azhar.azhar@muf.co.id | J9: =VLOOKUP(D9,'MAPPING MD & SKENARIO'!B:D,3,FALSE) -> 1.3 | K9: =J9*50% -> 0.65 | L9: 1 | M9: =ROUNDUP(SUM(J9:L9),0) -> 3
A10: 7 | B10: BYD001-07 | D10: Credit Approval (CA) | E10: Pengecekan dan lanjutan proses data kontrak pada Credit Approval (CA) | F10: 1. Akses menu Credit Approval 2. Lakukan pengecekan informasi pada Tab Order Digital di CA 3. Lakukan proses approval sampai full approved 4. Cek callback actcode tracking BSI dan tracking order MASS (Excel Lampiran BSI BYOND - Tracking BSI) | G10: 1. Berhasil masuk ke menu CA 2. Informasi pada Tab Order Digital sudah sesuai 3. Data kontrak berhasil full approved 4. Callback tracking BSI dan tracking order MASS sesuai | H10: =VLOOKUP(LEFT(B10,FIND("-",B10)-1),'MAPPING MD & SKENARIO'!$H$2:$I$42,2,FALSE) -> Azhar | I10: =VLOOKUP(H10,'MAPPING MD & SKENARIO'!$I$2:$J$42,2,FALSE) -> azhar.azhar@muf.co.id | J10: =VLOOKUP(D10,'MAPPING MD & SKENARIO'!B:D,3,FALSE) -> 2.6 | K10: =J10*50% -> 1.3 | L10: 1 | M10: =ROUNDUP(SUM(J10:L10),0) -> 5
A11: 8 | B11: BYD001-08 | D11: PO/CL | E11: Melakukan cetak PO | F11: 1. Akses menu PO 2. Lakukan proses cetak PO 3. Cek callback actcode tracking BSI dan tracking order MASS (Excel Lampiran BSI BYOND - Tracking BSI) | G11: 1. Berhasil masuk ke menu PO 2. Berhasil cetak PO 3. Callback tracking BSI dan tracking order MASS sesuai | H11: =VLOOKUP(LEFT(B11,FIND("-",B11)-1),'MAPPING MD & SKENARIO'!$H$2:$I$42,2,FALSE) -> Azhar | I11: =VLOOKUP(H11,'MAPPING MD & SKENARIO'!$I$2:$J$42,2,FALSE) -> azhar.azhar@muf.co.id | J11: =VLOOKUP(D11,'MAPPING MD & SKENARIO'!B:D,3,FALSE) -> 0.65 | K11: =J11*50% -> 0.325 | L11: 1 | M11: =ROUNDUP(SUM(J11:L11),0) -> 2
A12: 9 | B12: BYD001-09 | D12: FDE | E12: Proses Full Data Entry (FDE) untuk data kontrak terkait | F12: 1. Akses menu FDE 2. Lakukan pengecekan informasi pada Tab Order Digital di FDE 3. Proses inputan pada FDE 4. Konfirmasi FDE 5. Cek callback actcode tracking BSI dan tracking order MASS (Excel Lampiran BSI BYOND - Tracking BSI) | G12: 1. Berhasil masuk ke menu FDE 2. Informasi pada Tab Order Digital sudah sesuai 3. Proses input FDE berhasil 4. Callback tracking BSI dan tracking order MASS sesuai | H12: =VLOOKUP(LEFT(B12,FIND("-",B12)-1),'MAPPING MD & SKENARIO'!$H$2:$I$42,2,FALSE) -> Azhar | I12: =VLOOKUP(H12,'MAPPING MD & SKENARIO'!$I$2:$J$42,2,FALSE) -> azhar.azhar@muf.co.id | J12: =VLOOKUP(D12,'MAPPING MD & SKENARIO'!B:D,3,FALSE) -> 2.6 | K12: =J12*50% -> 1.3 | L12: 1 | M12: =ROUNDUP(SUM(J12:L12),0) -> 5
A13: 10 | B13: BYD001-10 | D13: Verifikasi Data-PPD | E13: Proses Verifikasi Data sampai dengan PPD untuk data kontrak terkait | F13: 1. Akses menu Verdat 2. Lakukan proses verdat sampai dengan PPD 3. Lakukan pengecekan informasi pada Tab Order Digital di Verdat 4. Konfirmasi proses Verdat 5. Save dan konfirmasi proses PPD 6. Cek callback actcode tracking BSI dan tracking order MASS (Excel Lampiran BSI BYOND - Tracking BSI) | G13: 1. Berhasil akses ke menu Verdat 2. Berhasil melakukan proses verdat sampai PPD 3. Informasi pada Tab Order Digital sudah sesuai 4. Berhasil konfirmasi proses verdat 5. Berhasil konfirmasi PPD 6. Callback tracking BSI dan tracking order MASS sesuai | H13: =VLOOKUP(LEFT(B13,FIND("-",B13)-1),'MAPPING MD & SKENARIO'!$H$2:$I$42,2,FALSE) -> Azhar | I13: =VLOOKUP(H13,'MAPPING MD & SKENARIO'!$I$2:$J$42,2,FALSE) -> azhar.azhar@muf.co.id | J13: =VLOOKUP(D13,'MAPPING MD & SKENARIO'!B:D,3,FALSE) -> 1.95 | K13: =J13*50% -> 0.975 | L13: 1 | M13: =ROUNDUP(SUM(J13:L13),0) -> 4
A14: 11 | B14: BYD001-11 | D14: FPD | E14: Proses FPD untuk data kontrak terkait | F14: 1. Akses menu FPD 2. Lakukan proses FPD | G14: 1. Berhasil akses menu FPD 2. Berhasil konfirmasi FPD | H14: =VLOOKUP(LEFT(B14,FIND("-",B14)-1),'MAPPING MD & SKENARIO'!$H$2:$I$42,2,FALSE) -> Azhar | I14: =VLOOKUP(H14,'MAPPING MD & SKENARIO'!$I$2:$J$42,2,FALSE) -> azhar.azhar@muf.co.id | J14: =VLOOKUP(D14,'MAPPING MD & SKENARIO'!B:D,3,FALSE) -> 0.65 | K14: =J14*50% -> 0.325 | L14: 1 | M14: =ROUNDUP(SUM(J14:L14),0) -> 2
A15: 12 | B15: BYD001-12 | D15: Detail Application - Tracking Order | E15: Melakukan pengecekan informasi Order Digital pada Detail App | F15: 1. Akses menu Tracking Order 2. Klik button aksi dan klik lagi button Detail Application 3. Lakukan pengecekan informasi pada Tab Order Digital di Detail App-Tracking Order | G15: 1. Berhasil akses ke menu Tracking Order 2. Berhasil klik button aksi dan button detail application 3. Informasi pada Tab Order Digital sudah sesuai | H15: =VLOOKUP(LEFT(B15,FIND("-",B15)-1),'MAPPING MD & SKENARIO'!$H$2:$I$42,2,FALSE) -> Azhar | I15: =VLOOKUP(H15,'MAPPING MD & SKENARIO'!$I$2:$J$42,2,FALSE) -> azhar.azhar@muf.co.id | J15: =VLOOKUP(D15,'MAPPING MD & SKENARIO'!B:D,3,FALSE) -> 0.65 | K15: =J15*50% -> 0.325 | L15: 1 | M15: =ROUNDUP(SUM(J15:L15),0) -> 2
A16: 13 | B16: BYD002-01 | C16: BS002 | D16: Web View BSI OTO | E16: Melakukan pengajuan data kontrak melalui Web View BSI BYOND | F16: 1. Akses menu Web View BSI BYOND 2. Melakukan inputan data kendaraan 3. Melakukan inputan simulasi pembiayaan 4. Melakukan inputan verifikasi data 5. Konfirmasi pengajuan | G16: 1. Berhasil akses menu Web View BSI BYOND 2. Berhasil melakukan inputan data kendaraan 3. Berhasil melakukan inputan simulasi pembiayaan 4. Berhasil melakukan inputan data nasabah 5. Berhasil submit pengajuan dari Web View BSI BYOND | H16: =VLOOKUP(LEFT(B16,FIND("-",B16)-1),'MAPPING MD & SKENARIO'!$H$2:$I$42,2,FALSE) -> Affinia | I16: =VLOOKUP(H16,'MAPPING MD & SKENARIO'!$I$2:$J$42,2,FALSE) -> affinia.by@muf.co.id | J16: =VLOOKUP(D16,'MAPPING MD & SKENARIO'!B:D,3,FALSE) -> 1.3 | K16: =J16*50% -> 0.65 | L16: 1 | M16: =ROUNDUP(SUM(J16:L16),0) -> 3
A17: 14 | B17: BYD002-02 | D17: CBAS Digital | E17: Melakukan proses verifikasi administrasi atas pengajuan yang dilakukan sebelumnya | F17: 1. Akses menu CBAS Digital 2. Lakukan pengecekan data yang sudah terhit ke CBAS Digital 3. Cek callback actcode Tracking BSI pada database (Excel Lampiran BSI BYOND - Tracking BSI) | G17: 1. Berhasil akses menu CBAS Digital 2. Hasil screening data pada CBAS Digital untuk Verifikasi Administrasi sudah sesuai 3. Callback actcode sudah sesuai | H17: =VLOOKUP(LEFT(B17,FIND("-",B17)-1),'MAPPING MD & SKENARIO'!$H$2:$I$42,2,FALSE) -> Affinia | I17: =VLOOKUP(H17,'MAPPING MD & SKENARIO'!$I$2:$J$42,2,FALSE) -> affinia.by@muf.co.id | J17: =VLOOKUP(D17,'MAPPING MD & SKENARIO'!B:D,3,FALSE) -> 1.95 | K17: =J17*50% -> 0.975 | L17: 1 | M17: =ROUNDUP(SUM(J17:L17),0) -> 4
A18: 15 | B18: BYD002-03 | D18: Email Notifikasi Submit Order | E18: Pengecekan kiriman data dan format email submit order | F18: 1. Buka e-mail 2. Pastikan e-email terkirim 3. Lakukan pengecekan format dan data pada kiriman e-mail | G18: 1. Berhasil akses e-mail 2. E-mail berhasil masuk ke Inbox 3. Format dan data terlampir pada e-mail sudah sesuai | H18: =VLOOKUP(LEFT(B18,FIND("-",B18)-1),'MAPPING MD & SKENARIO'!$H$2:$I$42,2,FALSE) -> Affinia | I18: =VLOOKUP(H18,'MAPPING MD & SKENARIO'!$I$2:$J$42,2,FALSE) -> affinia.by@muf.co.id | J18: =VLOOKUP(D18,'MAPPING MD & SKENARIO'!B:D,3,FALSE) -> 0.26 | K18: =J18*50% -> 0.13 | L18: 1 | M18: =ROUNDUP(SUM(J18:L18),0) -> 2
A19: 16 | B19: BYD002-04 | D19: Entry Form Digital | E19: Pengecekan dan lanjutkan inputan data kontrak pada EFD MASS | F19: 1. Akses menu EFD 2. Proses lanjutkan inputan data 3. Lakukan pengecekan pada mapping submit order data terkait autofill data, penambahan field baru dan penambahan label baru (Excel Lampiran BSI BYOND - Sheet Mapping Submit Order) 4. Konfirmasi EFD 5. Cek callback actcode tracking BSI dan tracking order MASS (Excel Lampiran BSI BYOND - Tracking BSI) | G19: 1. Berhasil akses EFD 2. Berhasil melanjutkan inputan data 3. Terkait autofill, penambahan field dan penambahan label di EFD sudah sesuai 4. Berhasil konfirmasi EFD 5. Callback tracking BSI dan tracking order MASS sesuai | H19: =VLOOKUP(LEFT(B19,FIND("-",B19)-1),'MAPPING MD & SKENARIO'!$H$2:$I$42,2,FALSE) -> Affinia | I19: =VLOOKUP(H19,'MAPPING MD & SKENARIO'!$I$2:$J$42,2,FALSE) -> affinia.by@muf.co.id | J19: =VLOOKUP(D19,'MAPPING MD & SKENARIO'!B:D,3,FALSE) -> 1.3 | K19: =J19*50% -> 0.65 | L19: 1 | M19: =ROUNDUP(SUM(J19:L19),0) -> 3
A20: 17 | B20: BYD002-05 | D20: Data Entry - Screening 2 | E20: Pengecekan dan proses lanjutkan inputan data kontrak pada SC2 | F20: 1. Akses menu To Do List SC2 2. Pengecekan penambahan informasi tipe order dan customer category pada tampilan data to do list sc2 3. Masuk ke form data entry SC2 4. Melakukan proses inputan data entry serta melakukan pengecekan mapping submit order data terkait autofill data, penambahan field baru dan penambahan label baru (Excel Lampiran BSI BYOND - Sheet Mapping Submit Order) 5. Input struktur kredit sesuai dengan matrix paket kredit (Excel Lampiran BSI BYOND - Sheet Matrix Paket Kredit Mobil Baru/Mobil Bekas/Motor Baru) 6. Konfirmasi data entry screening 2 7. Cek callback actcode tracking BSI dan tracking order MASS (Excel Lampiran BSI BYOND - Tracking BSI) | G20: 1. Berhasil masuk ke menu to do list SC2 2. Tambahan informasi pada tampilan to do list sudah sesuai 3. Berhasil masuk ke form data entry SC2 4. Berhasil menlanjutkan inputan dan autofill, penambahan field serta penambahan label sudah sesuai 5. Inputan struktur kredit sudah sesuai dengan matrix paket kredit 6. Berhasil konfirmasi 7. Callback tracking BSI dan tracking order MASS sesuai | H20: =VLOOKUP(LEFT(B20,FIND("-",B20)-1),'MAPPING MD & SKENARIO'!$H$2:$I$42,2,FALSE) -> Affinia | I20: =VLOOKUP(H20,'MAPPING MD & SKENARIO'!$I$2:$J$42,2,FALSE) -> affinia.by@muf.co.id | J20: =VLOOKUP(D20,'MAPPING MD & SKENARIO'!B:D,3,FALSE) -> 2.6 | K20: =J20*50% -> 1.3 | L20: 1 | M20: =ROUNDUP(SUM(J20:L20),0) -> 5
A21: 18 | B21: BYD002-06 | D21: Tele Survey | E21: Proses actcode terima offer dan lanjutkan inputan data kontrak pada Tele Survey | F21: 1. Akses menu Tele Survey 2. Cek validasi ketika BSI BYOND belum accept offer 3. Lakukan proses accept offer 4. Akses form Tele Survey 5. Klik button Detail Application pada Tele Survey dan lakukan pengecekan informasi data pada Tab Order Digital 6. Lanjutkan proses inputan data pada Tele Survey 7. Konfirmasi Tele Survey 8. Cek callback actcode tracking BSI dan tracking order MASS (Excel Lampiran BSI BYOND - Tracking BSI) | G21: 1. Berhasil masuk ke menu Tele Survey 2. Validasi belum accept offer sudah sesuai 3. Berhasil proses accept offer 4. Berhasil masuk ke form Tele Survey 5. Berhasil klik button Detail Application dan informasi pada Tab Order Digital sudah sesuai 6. Berhasil input Tele Survey 7. Berhasil konfirmasi Tele Survey 8. Callback tracking BSI dan tracking order MASS sesuai | H21: =VLOOKUP(LEFT(B21,FIND("-",B21)-1),'MAPPING MD & SKENARIO'!$H$2:$I$42,2,FALSE) -> Affinia | I21: =VLOOKUP(H21,'MAPPING MD & SKENARIO'!$I$2:$J$42,2,FALSE) -> affinia.by@muf.co.id | J21: =VLOOKUP(D21,'MAPPING MD & SKENARIO'!B:D,3,FALSE) -> 1.3 | K21: =J21*50% -> 0.65 | L21: 1 | M21: =ROUNDUP(SUM(J21:L21),0) -> 3
A22: 19 | B22: BYD002-07 | D22: KYC | E22: Proses return kontrak ke screening 3 pada menu KYC | F22: 1. Akses menu KYC 2. Klik button Detail Application pada KYC dan lakukan pengecekan informasi data pada Tab Order Digital 3. Lanjutkan proses inputan data pada KYC 4. Lakukan proses submit KYC Return to Screening 3 5. Cek callback actcode tracking BSI dan tracking order MASS (Excel Lampiran BSI BYOND - Tracking BSI) | G22: 1. Berhasil masuk ke menu KYC 2. Berhasil klik button Detail Application dan informasi pada Tab Order Digital sudah sesuai 3. Berhasil input KYC 4. Berhasil return to screening 3 5. Callback tracking BSI dan tracking order MASS sesuai | H22: =VLOOKUP(LEFT(B22,FIND("-",B22)-1),'MAPPING MD & SKENARIO'!$H$2:$I$42,2,FALSE) -> Affinia | I22: =VLOOKUP(H22,'MAPPING MD & SKENARIO'!$I$2:$J$42,2,FALSE) -> affinia.by@muf.co.id | J22: =VLOOKUP(D22,'MAPPING MD & SKENARIO'!B:D,3,FALSE) -> 1.3 | K22: =J22*50% -> 0.65 | L22: 1 | M22: =ROUNDUP(SUM(J22:L22),0) -> 3
A23: 20 | B23: BYD002-08 | D23: CBAS MASS | E23: Melakukan proses pengecekan inquiry data | F23: 1. Akses menu CBAS MASS 2. Lakukan pengecekan inquiry data yang sudah terhit ke CBAS MASS 3. Cek callback actcode Tracking BSI pada database (Excel Lampiran BSI BYOND - Tracking BSI) | G23: 1. Berhasil akses menu CBAS MASS 2. Hasil inquiry pada CBAS MASS sudah sesuai 3. Callback actcode sudah sesuai | H23: =VLOOKUP(LEFT(B23,FIND("-",B23)-1),'MAPPING MD & SKENARIO'!$H$2:$I$42,2,FALSE) -> Affinia | I23: =VLOOKUP(H23,'MAPPING MD & SKENARIO'!$I$2:$J$42,2,FALSE) -> affinia.by@muf.co.id | J23: =VLOOKUP(D23,'MAPPING MD & SKENARIO'!B:D,3,FALSE) -> 1.95 | K23: =J23*50% -> 0.975 | L23: 1 | M23: =ROUNDUP(SUM(J23:L23),0) -> 4
A24: 21 | B24: BYD002-09 | D24: Credit Approval (CA) | E24: Pengecekan dan lanjutkan proses data kontrak pada Credit Approval (CA) | F24: 1. Akses menu Credit Approval 2. Lakukan pengecekan informasi pada Tab Order Digital di CA 3. Lakukan proses RTRE pada tab Approval 4. Cek callback actcode tracking BSI dan tracking order MASS (Excel Lampiran BSI BYOND - Tracking BSI) | G24: 1. Berhasil masuk ke menu CA 2. Informasi pada Tab Order Digital sudah sesuai 3. Data kontrak berhasil masuk menu Approval Return 4. Callback tracking BSI dan tracking order MASS sesuai | H24: =VLOOKUP(LEFT(B24,FIND("-",B24)-1),'MAPPING MD & SKENARIO'!$H$2:$I$42,2,FALSE) -> Affinia | I24: =VLOOKUP(H24,'MAPPING MD & SKENARIO'!$I$2:$J$42,2,FALSE) -> affinia.by@muf.co.id | J24: =VLOOKUP(D24,'MAPPING MD & SKENARIO'!B:D,3,FALSE) -> 2.6 | K24: =J24*50% -> 1.3 | L24: 1 | M24: =ROUNDUP(SUM(J24:L24),0) -> 5
A25: 22 | B25: BYD002-10 | D25: RTRE | E25: Pengecekan dan proses RTRE dengan kondisi tanggal di bawah tanggal 15 | F25: 1. Akses menu RTRE 2. Lakukan perubahan data ketika proses RTRE di bawah tanggal 15 3. Submit proses RTRE | G25: 1. Berhasil akses menu RTRE 2. Data kontrak sesuai dan berhasil merubah data ketika proses RTRE di bawah tanggal 15 3. Berhasil submit proses RTRE | H25: =VLOOKUP(LEFT(B25,FIND("-",B25)-1),'MAPPING MD & SKENARIO'!$H$2:$I$42,2,FALSE) -> Affinia | I25: =VLOOKUP(H25,'MAPPING MD & SKENARIO'!$I$2:$J$42,2,FALSE) -> affinia.by@muf.co.id | J25: =VLOOKUP(D25,'MAPPING MD & SKENARIO'!B:D,3,FALSE) -> 1.95 | K25: =J25*50% -> 0.975 | L25: 1 | M25: =ROUNDUP(SUM(J25:L25),0) -> 4
A26: 23 | B26: BYD002-11 | D26: CBAS Digital | E26: Melakukan proses verifikasi administrasi atas pengajuan yang dilakukan sebelumnya | F26: 1. Akses menu CBAS Digital 2. Lakukan pengecekan data yang sudah terhit ke CBAS Digital di bawah tanggal 15 (Dedup) 3. Cek callback actcode Tracking BSI pada database (Excel Lampiran BSI BYOND - Tracking BSI) | G26: 1. Berhasil akses menu CBAS Digital 2. Hasil screening data pada CBAS Digital untuk Verifikasi Administrasi sudah sesuai di bawah tanggal 15 (Dedup) 3. Callback actcode sudah sesuai | H26: =VLOOKUP(LEFT(B26,FIND("-",B26)-1),'MAPPING MD & SKENARIO'!$H$2:$I$42,2,FALSE) -> Affinia | I26: =VLOOKUP(H26,'MAPPING MD & SKENARIO'!$I$2:$J$42,2,FALSE) -> affinia.by@muf.co.id | J26: =VLOOKUP(D26,'MAPPING MD & SKENARIO'!B:D,3,FALSE) -> 1.95 | K26: =J26*50% -> 0.975 | L26: 1 | M26: =ROUNDUP(SUM(J26:L26),0) -> 4
A27: 24 | B27: BYD002-12 | D27: Credit Approval (CA) | E27: Pengecekan dan lanjutkan proses data kontrak pada Credit Approval (CA) | F27: 1. Akses menu Credit Approval 2. Lakukan pengecekan informasi pada Tab Order Digital di CA 3. Lakukan proses approval sampai full approved 4. Cek callback actcode tracking BSI dan tracking order MASS (Excel Lampiran BSI BYOND - Tracking BSI) | G27: 1. Berhasil masuk ke menu CA 2. Informasi pada Tab Order Digital sudah sesuai 3. Data kontrak berhasil full approved 4. Callback tracking BSI dan tracking order MASS sesuai | H27: =VLOOKUP(LEFT(B27,FIND("-",B27)-1),'MAPPING MD & SKENARIO'!$H$2:$I$42,2,FALSE) -> Affinia | I27: =VLOOKUP(H27,'MAPPING MD & SKENARIO'!$I$2:$J$42,2,FALSE) -> affinia.by@muf.co.id | J27: =VLOOKUP(D27,'MAPPING MD & SKENARIO'!B:D,3,FALSE) -> 2.6 | K27: =J27*50% -> 1.3 | L27: 1 | M27: =ROUNDUP(SUM(J27:L27),0) -> 5
A28: 25 | B28: BYD002-13 | D28: PO/CL | E28: Melakukan cetak PO | F28: 1. Akses menu PO 2. Lakukan proses cetak PO 3. Cek callback actcode tracking BSI dan tracking order MASS (Excel Lampiran BSI BYOND - Tracking BSI) | G28: 1. Berhasil masuk ke menu PO 2. Berhasil cetak PO 3. Callback tracking BSI dan tracking order MASS sesuai | H28: =VLOOKUP(LEFT(B28,FIND("-",B28)-1),'MAPPING MD & SKENARIO'!$H$2:$I$42,2,FALSE) -> Affinia | I28: =VLOOKUP(H28,'MAPPING MD & SKENARIO'!$I$2:$J$42,2,FALSE) -> affinia.by@muf.co.id | J28: =VLOOKUP(D28,'MAPPING MD & SKENARIO'!B:D,3,FALSE) -> 0.65 | K28: =J28*50% -> 0.325 | L28: 1 | M28: =ROUNDUP(SUM(J28:L28),0) -> 2
... A32: 29 | B32: BYD002-17 | D32: Detail Application - Tracking Order | E32: Melakukan pengecekan informasi Order Digital pada Detail App | F32: 1. Akses menu Tracking Order 2. Klik button aksi dan klik lagi button Detail Application 3. Lakukan pengecekan informasi pada Tab Order Digital di Detail App-Tracking Order | G32: 1. Berhasil akses ke menu Tracking Order 2. Berhasil klik button aksi dan button detail application 3. Informasi pada Tab Order Digital sudah sesuai | H32: =VLOOKUP(LEFT(B32,FIND("-",B32)-1),'MAPPING MD & SKENARIO'!$H$2:$I$42,2,FALSE) -> Affinia | I32: =VLOOKUP(H32,'MAPPING MD & SKENARIO'!$I$2:$J$42,2,FALSE) -> affinia.by@muf.co.id | J32: =VLOOKUP(D32,'MAPPING MD & SKENARIO'!B:D,3,FALSE) -> 0.65 | K32: =J32*50% -> 0.325 | L32: 1 | M32: =ROUNDUP(SUM(J32:L32),0) -> 2
A33: 30 | B33: BYD003-01 | C33: BS003 | D33: Web View BSI OTO | E33: Melakukan pengajuan data kontrak melalui Web View BSI BYOND | F33: 1. Akses menu Web View BSI BYOND 2. Melakukan inputan data kendaraan 3. Melakukan inputan simulasi pembiayaan 4. Melakukan inputan verifikasi data 5. Konfirmasi pengajuan | G33: 1. Berhasil akses menu Web View BSI BYOND 2. Berhasil melakukan inputan data kendaraan 3. Berhasil melakukan inputan simulasi pembiayaan 4. Berhasil melakukan inputan data nasabah 5. Berhasil submit pengajuan dari Web View BSI BYOND | H33: =VLOOKUP(LEFT(B33,FIND("-",B33)-1),'MAPPING MD & SKENARIO'!$H$2:$I$42,2,FALSE) -> Kevin | I33: =VLOOKUP(H33,'MAPPING MD & SKENARIO'!$I$2:$J$42,2,FALSE) -> kevin.hardianus@muf.co.id | J33: =VLOOKUP(D33,'MAPPING MD & SKENARIO'!B:D,3,FALSE) -> 1.3 | K33: =J33*50% -> 0.65 | L33: 1 | M33: =ROUNDUP(SUM(J33:L33),0) -> 3
A34: 31 | B34: BYD003-02 | D34: CBAS Digital | E34: Melakukan proses verifikasi administrasi atas pengajuan yang dilakukan sebelumnya | F34: 1. Akses menu CBAS Digital 2. Lakukan pengecekan data yang sudah terhit ke CBAS Digital 3. Cek callback actcode Tracking BSI pada database (Excel Lampiran BSI BYOND - Tracking BSI) | G34: 1. Berhasil akses menu CBAS Digital 2. Hasil screening data pada CBAS Digital untuk Verifikasi Administrasi sudah sesuai 3. Callback actcode sudah sesuai | H34: =VLOOKUP(LEFT(B34,FIND("-",B34)-1),'MAPPING MD & SKENARIO'!$H$2:$I$42,2,FALSE) -> Kevin | I34: =VLOOKUP(H34,'MAPPING MD & SKENARIO'!$I$2:$J$42,2,FALSE) -> kevin.hardianus@muf.co.id | J34: =VLOOKUP(D34,'MAPPING MD & SKENARIO'!B:D,3,FALSE) -> 1.95 | K34: =J34*50% -> 0.975 | L34: 1 | M34: =ROUNDUP(SUM(J34:L34),0) -> 4
A35: 32 | B35: BYD003-03 | D35: Email Notifikasi Submit Order | E35: Pengecekan kiriman data dan format email submit order | F35: 1. Buka e-mail 2. Pastikan e-email terkirim 3. Lakukan pengecekan format dan data pada kiriman e-mail | G35: 1. Berhasil akses e-mail 2. E-mail berhasil masuk ke Inbox 3. Format dan data terlampir pada e-mail sudah sesuai | H35: =VLOOKUP(LEFT(B35,FIND("-",B35)-1),'MAPPING MD & SKENARIO'!$H$2:$I$42,2,FALSE) -> Kevin | I35: =VLOOKUP(H35,'MAPPING MD & SKENARIO'!$I$2:$J$42,2,FALSE) -> kevin.hardianus@muf.co.id | J35: =VLOOKUP(D35,'MAPPING MD & SKENARIO'!B:D,3,FALSE) -> 0.26 | K35: =J35*50% -> 0.13 | L35: 1 | M35: =ROUNDUP(SUM(J35:L35),0) -> 2
A36: 33 | B36: BYD003-04 | D36: Entry Form Digital | E36: Pengecekan dan lanjutan inputan data kontrak pada EFD MASS | F36: 1. Akses menu EFD 2. Proses lanjutan inputan data 3. Lakukan pengecekan pada mapping submit order data terkait autofill data, penambahan field baru dan penambahan label baru (Excel Lampiran BSI BYOND - Sheet Mapping Submit Order) 4. Konfirmasi EFD 5. Cek callback actcode tracking BSI dan tracking order MASS (Excel Lampiran BSI BYOND - Tracking BSI) | G36: 1. Berhasil akses EFD 2. Berhasil melanjutkan inputan data 3. Terkait autofill, penambahan field dan penambahan label di EFD sudah sesuai 4. Berhasil konfirmasi EFD 5. Callback tracking BSI dan tracking order MASS sesuai | H36: =VLOOKUP(LEFT(B36,FIND("-",B36)-1),'MAPPING MD & SKENARIO'!$H$2:$I$42,2,FALSE) -> Kevin | I36: =VLOOKUP(H36,'MAPPING MD & SKENARIO'!$I$2:$J$42,2,FALSE) -> kevin.hardianus@muf.co.id | J36: =VLOOKUP(D36,'MAPPING MD & SKENARIO'!B:D,3,FALSE) -> 1.3 | K36: =J36*50% -> 0.65 | L36: 1 | M36: =ROUNDUP(SUM(J36:L36),0) -> 3
A37: 34 | B37: BYD003-05 | D37: Data Entry - Screening 2 | E37: Pengecekan dan proses lanjutan inputan data kontrak pada SC2 | F37: 1. Akses menu To Do List SC2 2. Pengecekan penambahan informasi tipe order dan customer category pada tampilan data to do list sc2 3. Masuk ke form data entry SC2 4. Melakukan proses inputan data entry serta melakukan pengecekan mapping submit order data terkait autofill data, penambahan field baru dan penambahan label baru (Excel Lampiran BSI BYOND - Sheet Mapping Submit Order) 5. Input struktur kredit sesuai dengan matrix paket kredit (Excel Lampiran BSI BYOND - Sheet Matrix Paket Kredit Mobil Baru/Mobil Bekas/Motor Baru) 6. Konfirmasi data entry screening 2 7. Cek callback actcode tracking BSI dan tracking order MASS (Excel Lampiran BSI BYOND - Tracking BSI) | G37: 1. Berhasil masuk ke menu to do list SC2 2. Tambahan informasi pada tampilan to do list sudah sesuai 3. Berhasil masuk ke form data entry SC2 4. Berhasil menlanjutkan inputan dan autofill, penambahan field serta penambahan label sudah sesuai 5. Inputan struktur kredit sudah sesuai dengan matrix paket kredit 6. Berhasil konfirmasi 7. Callback tracking BSI dan tracking order MASS sesuai | H37: =VLOOKUP(LEFT(B37,FIND("-",B37)-1),'MAPPING MD & SKENARIO'!$H$2:$I$42,2,FALSE) -> Kevin | I37: =VLOOKUP(H37,'MAPPING MD & SKENARIO'!$I$2:$J$42,2,FALSE) -> kevin.hardianus@muf.co.id | J37: =VLOOKUP(D37,'MAPPING MD & SKENARIO'!B:D,3,FALSE) -> 2.6 | K37: =J37*50% -> 1.3 | L37: 1 | M37: =ROUNDUP(SUM(J37:L37),0) -> 5
A38: 35 | B38: BYD003-06 | D38: Reguler Survey | E38: Proses actcode terima offer dan lanjutan inputan data kontrak pada Reguler Survey | F38: 1. Akses menu Reguler Survey 2. Cek validasi ketika BSI BYOND belum accept offer 3. Lakukan proses accept offer 4. Akses form Reguler Survey 5. Klik button Detail Application pada Reguler Survey dan lakukan pengecekan informasi data pada Tab Order Digital 6. Lanjutan proses inputan data pada Reguler Survey 7. Konfirmasi Reguler Survey 8. Cek callback actcode tracking BSI dan tracking order MASS (Excel Lampiran BSI BYOND - Tracking BSI) | G38: 1. Berhasil masuk ke menu Reguler Survey 2. Validasi belum accept offer sudah sesuai 3. Berhasil proses accept offer 4. Berhasil masuk ke form Reguler Survey 5. Berhasil klik button Detail Application dan informasi pada Tab Order Digital sudah sesuai 6. Berhasil input Reguler Survey 7. Berhasil konfirmasi Reguler Survey 8. Callback tracking BSI dan tracking order MASS sesuai | H38: =VLOOKUP(LEFT(B38,FIND("-",B38)-1),'MAPPING MD & SKENARIO'!$H$2:$I$42,2,FALSE) -> Kevin | I38: =VLOOKUP(H38,'MAPPING MD & SKENARIO'!$I$2:$J$42,2,FALSE) -> kevin.hardianus@muf.co.id | J38: =VLOOKUP(D38,'MAPPING MD & SKENARIO'!B:D,3,FALSE) -> 1.3 | K38: =J38*50% -> 0.65 | L38: 1 | M38: =ROUNDUP(SUM(J38:L38),0) -> 3
A39: 36 | B39: BYD003-07 | D39: Credit Approval (CA) | E39: Pengecekan dan lanjutan proses data kontrak pada Credit Approval (CA) | F39: 1. Akses menu Credit Approval 2. Lakukan pengecekan informasi pada Tab Order Digital di CA 3. Lakukan proses approval sampai full approved 4. Cek callback actcode tracking BSI dan tracking order MASS (Excel Lampiran BSI BYOND - Tracking BSI) | G39: 1. Berhasil masuk ke menu CA 2. Informasi pada Tab Order Digital sudah sesuai 3. Data kontrak berhasil full approved 4. Callback tracking BSI dan tracking order MASS sesuai | H39: =VLOOKUP(LEFT(B39,FIND("-",B39)-1),'MAPPING MD & SKENARIO'!$H$2:$I$42,2,FALSE) -> Kevin | I39: =VLOOKUP(H39,'MAPPING MD & SKENARIO'!$I$2:$J$42,2,FALSE) -> kevin.hardianus@muf.co.id | J39: =VLOOKUP(D39,'MAPPING MD & SKENARIO'!B:D,3,FALSE) -> 2.6 | K39: =J39*50% -> 1.3 | L39: 1 | M39: =ROUNDUP(SUM(J39:L39),0) -> 5
A40: 37 | B40: BYD003-08 | D40: PO/CL | E40: Melakukan cetak PO | F40: 1. Akses menu PO 2. Lakukan proses cetak PO 3. Cek callback actcode tracking BSI dan tracking order MASS (Excel Lampiran BSI BYOND - Tracking BSI) | G40: 1. Berhasil masuk ke menu PO 2. Berhasil cetak PO 3. Callback tracking BSI dan tracking order MASS sesuai | H40: =VLOOKUP(LEFT(B40,FIND("-",B40)-1),'MAPPING MD & SKENARIO'!$H$2:$I$42,2,FALSE) -> Kevin | I40: =VLOOKUP(H40,'MAPPING MD & SKENARIO'!$I$2:$J$42,2,FALSE) -> kevin.hardianus@muf.co.id | J40: =VLOOKUP(D40,'MAPPING MD & SKENARIO'!B:D,3,FALSE) -> 0.65 | K40: =J40*50% -> 0.325 | L40: 1 | M40: =ROUNDUP(SUM(J40:L40),0) -> 2
A41: 38 | B41: BYD003-09 | D41: FDE | E41: Proses Full Data Entry (FDE) untuk data kontrak terkait | F41: 1. Akses menu FDE 2. Lakukan pengecekan informasi pada Tab Order Digital di FDE 3. Proses inputan pada FDE 4. Konfirmasi FDE 5. Cek callback actcode tracking BSI dan tracking order MASS (Excel Lampiran BSI BYOND - Tracking BSI) | G41: 1. Berhasil masuk ke menu FDE 2. Informasi pada Tab Order Digital sudah sesuai 3. Proses input FDE berhasil 4. Callback tracking BSI dan tracking order MASS sesuai | H41: =VLOOKUP(LEFT(B41,FIND("-",B41)-1),'MAPPING MD & SKENARIO'!$H$2:$I$42,2,FALSE) -> Kevin | I41: =VLOOKUP(H41,'MAPPING MD & SKENARIO'!$I$2:$J$42,2,FALSE) -> kevin.hardianus@muf.co.id | J41: =VLOOKUP(D41,'MAPPING MD & SKENARIO'!B:D,3,FALSE) -> 2.6 | K41: =J41*50% -> 1.3 | L41: 1 | M41: =ROUNDUP(SUM(J41:L41),0) -> 5
A42: 39 | B42: BYD003-10 | D42: Verifikasi Data-PPD | E42: Proses Verifikasi Data sampai dengan PPD untuk data kontrak terkait | F42: 1. Akses menu Verdat 2. Lakukan proses verdat sampai dengan PPD 3. Lakukan pengecekan informasi pada Tab Order Digital di Verdat 4. Konfirmasi proses Verdat 5. Save dan konfirmasi proses PPD 6. Cek callback actcode tracking BSI dan tracking order MASS (Excel Lampiran BSI BYOND - Tracking BSI) | G42: 1. Berhasil akses ke menu Verdat 2. Berhasil melakukan proses verdat sampai PPD 3. Informasi pada Tab Order Digital sudah sesuai 4. Berhasil konfirmasi proses verdat 5. Berhasil konfirmasi PPD 6. Callback tracking BSI dan tracking order MASS sesuai | H42: =VLOOKUP(LEFT(B42,FIND("-",B42)-1),'MAPPING MD & SKENARIO'!$H$2:$I$42,2,FALSE) -> Kevin | I42: =VLOOKUP(H42,'MAPPING MD & SKENARIO'!$I$2:$J$42,2,FALSE) -> kevin.hardianus@muf.co.id | J42: =VLOOKUP(D42,'MAPPING MD & SKENARIO'!B:D,3,FALSE) -> 1.95 | K42: =J42*50% -> 0.975 | L42: 1 | M42: =ROUNDUP(SUM(J42:L42),0) -> 4
A43: 40 | B43: BYD003-11 | D43: FPD | E43: Proses FPD untuk data kontrak terkait | F43: 1. Akses menu FPD 2. Lakukan proses FPD | G43: 1. Berhasil akses menu FPD 2. Berhasil konfirmasi FPD | H43: =VLOOKUP(LEFT(B43,FIND("-",B43)-1),'MAPPING MD & SKENARIO'!$H$2:$I$42,2,FALSE) -> Kevin | I43: =VLOOKUP(H43,'MAPPING MD & SKENARIO'!$I$2:$J$42,2,FALSE) -> kevin.hardianus@muf.co.id | J43: =VLOOKUP(D43,'MAPPING MD & SKENARIO'!B:D,3,FALSE) -> 0.65 | K43: =J43*50% -> 0.325 | L43: 1 | M43: =ROUNDUP(SUM(J43:L43),0) -> 2
...

Sheet DASHBOARD PROGRESS
A1: No | B1: Scenario ID | C1: Total Task | D1: Task Done | E1: Status | F1: PIC | G1: Notes
A2: ='TEST CASES'!A4 -> 1 | B2: ='TEST CASES'!B4 -> BYD001-01 | C2: =IF('TEST CASES'!F4="", 0, LEN(TRIM('TEST CASES'!F4))-LEN(SUBSTITUTE('TEST CASES'!F4, CHAR(10), ""))+1) -> 5 | E2: =IF(D2=0,"Open",IF(D2=C2,"Done","InProgress")) -> Open | F2: ='TEST CASES'!H4 -> Azhar
A3: ='TEST CASES'!A5 -> 2 | B3: ='TEST CASES'!B5 -> BYD001-02 | C3: =IF('TEST CASES'!F5="", 0, LEN(TRIM('TEST CASES'!F5))-LEN(SUBSTITUTE('TEST CASES'!F5, CHAR(10), ""))+1) -> 4 | E3: =IF(D3=0,"Open",IF(D3=C3,"Done","InProgress")) -> Open | F3: ='TEST CASES'!H5 -> Azhar
A4: ='TEST CASES'!A6 -> 3 | B4: ='TEST CASES'!B6 -> BYD001-03 | C4: =IF('TEST CASES'!F6="", 0, LEN(TRIM('TEST CASES'!F6))-LEN(SUBSTITUTE('TEST CASES'!F6, CHAR(10), ""))+1) -> 3 | E4: =IF(D4=0,"Open",IF(D4=C4,"Done","InProgress")) -> Open | F4: ='TEST CASES'!H6 -> Azhar
A5: ='TEST CASES'!A7 -> 4 | B5: ='TEST CASES'!B7 -> BYD001-04 | C5: =IF('TEST CASES'!F7="", 0, LEN(TRIM('TEST CASES'!F7))-LEN(SUBSTITUTE('TEST CASES'!F7, CHAR(10), ""))+1) -> 7 | E5: =IF(D5=0,"Open",IF(D5=C5,"Done","InProgress")) -> Open | F5: ='TEST CASES'!H7 -> Azhar
A6: ='TEST CASES'!A8 -> 5 | B6: ='TEST CASES'!B8 -> BYD001-05 | C6: =IF('TEST CASES'!F8="", 0, LEN(TRIM('TEST CASES'!F8))-LEN(SUBSTITUTE('TEST CASES'!F8, CHAR(10), ""))+1) -> 10 | E6: =IF(D6=0,"Open",IF(D6=C6,"Done","InProgress")) -> Open | F6: ='TEST CASES'!H8 -> Azhar
A7: ='TEST CASES'!A9 -> 6 | B7: ='TEST CASES'!B9 -> BYD001-06 | C7: =IF('TEST CASES'!F9="", 0, LEN(TRIM('TEST CASES'!F9))-LEN(SUBSTITUTE('TEST CASES'!F9, CHAR(10), ""))+1) -> 9 | E7: =IF(D7=0,"Open",IF(D7=C7,"Done","InProgress")) -> Open | F7: ='TEST CASES'!H9 -> Azhar
A8: ='TEST CASES'!A10 -> 7 | B8: ='TEST CASES'!B10 -> BYD001-07 | C8: =IF('TEST CASES'!F10="", 0, LEN(TRIM('TEST CASES'!F10))-LEN(SUBSTITUTE('TEST CASES'!F10, CHAR(10), ""))+1) -> 5 | E8: =IF(D8=0,"Open",IF(D8=C8,"Done","InProgress")) -> Open | F8: ='TEST CASES'!H10 -> Azhar
A9: ='TEST CASES'!A11 -> 8 | B9: ='TEST CASES'!B11 -> BYD001-08 | C9: =IF('TEST CASES'!F11="", 0, LEN(TRIM('TEST CASES'!F11))-LEN(SUBSTITUTE('TEST CASES'!F11, CHAR(10), ""))+1) -> 4 | E9: =IF(D9=0,"Open",IF(D9=C9,"Done","InProgress")) -> Open | F9: ='TEST CASES'!H11 -> Azhar
A10: ='TEST CASES'!A12 -> 9 | B10: ='TEST CASES'!B12 -> BYD001-09 | C10: =IF('TEST CASES'!F12="", 0, LEN(TRIM('TEST CASES'!F12))-LEN(SUBSTITUTE('TEST CASES'!F12, CHAR(10), ""))+1) -> 6 | E10: =IF(D10=0,"Open",IF(D10=C10,"Done","InProgress")) -> Open | F10: ='TEST CASES'!H12 -> Azhar
A11: ='TEST CASES'!A13 -> 10 | B11: ='TEST CASES'!B13 -> BYD001-10 | C11: =IF('TEST CASES'!F13="", 0, LEN(TRIM('TEST CASES'!F13))-LEN(SUBSTITUTE('TEST CASES'!F13, CHAR(10), ""))+1) -> 7 | E11: =IF(D11=0,"Open",IF(D11=C11,"Done","InProgress")) -> Open | F11: ='TEST CASES'!H13 -> Azhar
A12: ='TEST CASES'!A14 -> 11 | B12: ='TEST CASES'!B14 -> BYD001-11 | C12: =IF('TEST CASES'!F14="", 0, LEN(TRIM('TEST CASES'!F14))-LEN(SUBSTITUTE('TEST CASES'!F14, CHAR(10), ""))+1) -> 2 | E12: =IF(D12=0,"Open",IF(D12=C12,"Done","InProgress")) -> Open | F12: ='TEST CASES'!H14 -> Azhar
A13: ='TEST CASES'!A15 -> 12 | B13: ='TEST CASES'!B15 -> BYD001-12 | C13: =IF('TEST CASES'!F15="", 0, LEN(TRIM('TEST CASES'!F15))-LEN(SUBSTITUTE('TEST CASES'!F15, CHAR(10), ""))+1) -> 3 | E13: =IF(D13=0,"Open",IF(D13=C13,"Done","InProgress")) -> Open | F13: ='TEST CASES'!H15 -> Azhar
... A316: ='TEST CASES'!A318 -> 348 | B316: ='TEST CASES'!B318 -> BYD041-03 | C316: =IF('TEST CASES'!F318="", 0, LEN(TRIM('TEST CASES'!F318))-LEN(SUBSTITUTE('TEST CASES'!F318, CHAR(10), ""))+1) -> 2 | E316: =IF(D316=0,"Open",IF(D316=C316,"Done","InProgress")) -> Open | F316: ='TEST CASES'!H318 -> Rasya

Sheet DEFECT LOG
A1: No | B1: Kode Skenario | C1: Aplikasi/Modul | D1: Keterangan Issue | E1: Rootcause | F1: Category Issue | G1: Severity | H1: Link Jira | I1: PIC UAT | J1: PIC OPR | K1: PIC Dev | L1: Issue Start | M1: Issue Solved | N1: Status | O1: Ready To Testing (Y/N) | P1: Tgl Retest | Q1: Hasil Retest | R1: Keterangan
A46: 45
A47: 46
A48: 47
A49: 48
A50: 49
A51: 50
A52: 51
A53: 52
A54: 53
A55: 54
A56: 55
A57: 56
... A102: 100

Sheet PANDUAN
A1: Panduan Penggunaan Template RTM
A2: Tujuan: RTM menautkan setiap requirement ke test scenario/test case, hasil uji, dan defect sehingga cakupan pengujian dapat dipastikan dan audit trail terjaga.
A3: Langkah pemakaian:
A4: 1) Isi kolom Req ID, Deskripsi, Tipe, Prioritas, Sumber, Versi, dan Owner.
A5: 2) Mapping ke artefak: Modul/Komponen dan Link ke Dokumen Desain (FS/TS).
A6: 3) Buat/isi Test Scenario ID dan Test Case ID; cantumkan Referensi Data Uji.
A7: 4) Tentukan Siklus Uji (SIT/UAT) dan update Status Pengujian setiap eksekusi.
A8: 5) Jika ada kegagalan, isi Defect ID, Severity, Status Defect, dan catatan hasil uji.
A9: 6) Update Coverage Status (Covered/Partial/Gap) untuk memantau kekosongan cakupan.
A10: 7) Untuk NFR, isi Jenis NFR (mis. Performance/Security) dan Target MetriK (mis. p95 ≤ 2s).
A11: 8) Update Tanggal dan PIC Update setiap perubahan; catat Baseline/Change Log bila ada CR.
A12: Tips:
... A16: Dashboard terisi otomatis berdasarkan data di RTM (baris 2–1000).

Sheet LOOKUP
A1: Tipe Requirement | B1: Prioritas | C1: Sumber | D1: Siklus Uji | E1: Status Pengujian | F1: Severity Defect | G1: Status Defect | H1: Coverage Status | I1: Jenis NFR
A2: BR - Bisnis | B2: Must have | C2: BRD | D2: SIT1 | E2: Not Run | F2: Critical | G2: Open | H2: Covered | I2: Performance
A3: FR - Fungsional | B3: Should have | C3: FRD | D3: SIT2 | E3: Pass | F3: High | G3: In Progress | H3: Partial | I3: Security
A4: NFR - Non-Fungsional | B4: Could have | C4: CR | D4: SIT3 | E4: Fail | F4: Medium | G4: Fixed | H4: Gap | I4: Reliability
A5: Regulatory/Compliance | B5: Won't have | C5: Regulasi | D5: UAT1 | E5: Blocked | F5: Low | G5: Verified | I5: Availability
A6: Lainnya | B6: High | C6: RFC | D6: UAT2 | F6: Trivial | G6: Closed | I6: Maintainability
B7: Medium | C7: User Story | D7: Regression | G7: Deferred | I7: Compatibility
B8: Low | C8: Epic | D8: Smoke | G8: Rejected | I8: Usability
G9: Duplicate | I9: Scalability
I10: Compliance

Sheet RTM
A1: Req ID | B1: Deskripsi Requirement | C1: Tipe Requirement | D1: Prioritas | E1: Sumber | F1: Versi Requirement | G1: Owner Requirement | H1: Modul/Komponen | I1: Link ke Dokumen Desain (FS/TS) | J1: Test Scenario ID | K1: Test Case ID | L1: Referensi Data Uji | M1: Siklus Uji | N1: Status Pengujian | O1: Catatan Hasil Uji | P1: Defect ID | Q1: Severity Defect | R1: Status Defect | S1: Coverage Status | T1: Tanggal Update | U1: PIC Update | V1: Baseline/Change Log | W1: Risiko/Impact | X1: Jenis NFR | Y1: Target NFR/MetriK
A2: REQ001 | B2: =#REF! -> #REF! | C2: FR - Fungsional | D2: Must have | E2: BRD | F2: v1.0 | H2: =#REF! -> #REF! | J2: =#REF! -> #REF! | M2: UAT1 | N2: Not Run | U2: =#REF! -> #REF!
A3: REQ002 | B3: =#REF! -> #REF! | C3: FR - Fungsional | D3: Must have | E3: BRD | F3: v1.0 | H3: =#REF! -> #REF! | J3: =#REF! -> #REF! | M3: UAT1 | N3: Not Run | U3: =#REF! -> #REF!
A4: REQ003 | B4: =#REF! -> #REF! | C4: FR - Fungsional | D4: Must have | E4: BRD | F4: v1.0 | H4: =#REF! -> #REF! | J4: =#REF! -> #REF! | M4: UAT1 | N4: Not Run | U4: =#REF! -> #REF!
A5: REQ004 | B5: =#REF! -> #REF! | C5: FR - Fungsional | D5: Must have | E5: BRD | F5: v1.0 | H5: =#REF! -> #REF! | J5: =#REF! -> #REF! | M5: UAT1 | N5: Not Run | U5: =#REF! -> #REF!
A6: REQ005 | B6: =#REF! -> #REF! | C6: FR - Fungsional | D6: Must have | E6: BRD | F6: v1.0 | H6: =#REF! -> #REF! | J6: =#REF! -> #REF! | M6: UAT1 | N6: Not Run | U6: =#REF! -> #REF!
A7: REQ006 | B7: =#REF! -> #REF! | C7: FR - Fungsional | D7: Must have | E7: BRD | F7: v1.0 | H7: =#REF! -> #REF! | J7: =#REF! -> #REF! | M7: UAT1 | N7: Not Run | U7: =#REF! -> #REF!
A8: REQ007 | B8: =#REF! -> #REF! | C8: FR - Fungsional | D8: Must have | E8: BRD | F8: v1.0 | H8: =#REF! -> #REF! | J8: =#REF! -> #REF! | M8: UAT1 | N8: Not Run | U8: =#REF! -> #REF!
A9: REQ008 | B9: =#REF! -> #REF! | C9: FR - Fungsional | D9: Must have | E9: BRD | F9: v1.0 | H9: =#REF! -> #REF! | J9: =#REF! -> #REF! | M9: UAT1 | N9: Not Run | U9: =#REF! -> #REF!
A10: REQ009 | B10: =#REF! -> #REF! | C10: FR - Fungsional | D10: Must have | E10: BRD | F10: v1.0 | H10: =#REF! -> #REF! | J10: =#REF! -> #REF! | M10: UAT1 | N10: Not Run | U10: =#REF! -> #REF!
A11: REQ010 | B11: =#REF! -> #REF! | C11: FR - Fungsional | D11: Must have | E11: BRD | F11: v1.0 | H11: =#REF! -> #REF! | J11: =#REF! -> #REF! | M11: UAT1 | N11: Not Run | U11: =#REF! -> #REF!
A12: REQ011 | B12: =#REF! -> #REF! | C12: FR - Fungsional | D12: Must have | E12: BRD | F12: v1.0 | H12: =#REF! -> #REF! | J12: =#REF! -> #REF! | M12: UAT1 | N12: Not Run | U12: =#REF! -> #REF!
A13: REQ012 | B13: =#REF! -> #REF! | C13: FR - Fungsional | D13: Must have | E13: BRD | F13: v1.0 | H13: =#REF! -> #REF! | J13: =#REF! -> #REF! | M13: UAT1 | N13: Not Run | U13: =#REF! -> #REF!
... A123: REQ122 | B123: =#REF! -> #REF! | C123: FR - Fungsional | D123: Must have | E123: BRD | F123: v1.0 | H123: =#REF! -> #REF! | J123: =#REF! -> #REF! | M123: UAT1 | N123: Not Run | U123: =#REF! -> #REF!
A124: REQ123 | C124: FR - Fungsional | D124: Must have | E124: BRD | F124: v1.0 | H124: =#REF! -> #REF! | J124: =#REF! -> #REF! | M124: UAT1 | N124: Not Run | U124: =#REF! -> #REF!
A125: REQ124 | C125: FR - Fungsional | D125: Must have | E125: BRD | F125: v1.0 | H125: =#REF! -> #REF! | J125: =#REF! -> #REF! | M125: UAT1 | N125: Not Run | U125: =#REF! -> #REF!
A126: REQ125 | C126: FR - Fungsional | D126: Must have | E126: BRD | F126: v1.0 | H126: =#REF! -> #REF! | J126: =#REF! -> #REF! | M126: UAT1 | N126: Not Run | U126: =#REF! -> #REF!
A127: REQ126 | C127: FR - Fungsional | D127: Must have | E127: BRD | F127: v1.0 | H127: =#REF! -> #REF! | J127: =#REF! -> #REF! | M127: UAT1 | N127: Not Run | U127: =#REF! -> #REF!
A128: REQ127 | C128: FR - Fungsional | D128: Must have | E128: BRD | F128: v1.0 | H128: =#REF! -> #REF! | J128: =#REF! -> #REF! | M128: UAT1 | N128: Not Run | U128: =#REF! -> #REF!
A129: REQ128 | C129: FR - Fungsional | D129: Must have | E129: BRD | F129: v1.0 | H129: =#REF! -> #REF! | J129: =#REF! -> #REF! | M129: UAT1 | N129: Not Run | U129: =#REF! -> #REF!
A130: REQ129 | C130: FR - Fungsional | D130: Must have | E130: BRD | F130: v1.0 | H130: =#REF! -> #REF! | J130: =#REF! -> #REF! | M130: UAT1 | N130: Not Run | U130: =#REF! -> #REF!
A131: REQ130 | C131: FR - Fungsional | D131: Must have | E131: BRD | F131: v1.0 | H131: =#REF! -> #REF! | J131: =#REF! -> #REF! | M131: UAT1 | N131: Not Run | U131: =#REF! -> #REF!
A132: REQ131 | C132: FR - Fungsional | D132: Must have | E132: BRD | F132: v1.0 | H132: =#REF! -> #REF! | J132: =#REF! -> #REF! | M132: UAT1 | N132: Not Run | U132: =#REF! -> #REF!
A133: REQ132 | C133: FR - Fungsional | D133: Must have | E133: BRD | F133: v1.0 | H133: =#REF! -> #REF! | J133: =#REF! -> #REF! | M133: UAT1 | N133: Not Run | U133: =#REF! -> #REF!
A134: REQ133 | C134: FR - Fungsional | D134: Must have | E134: BRD | F134: v1.0 | H134: =#REF! -> #REF! | J134: =#REF! -> #REF! | M134: UAT1 | N134: Not Run | U134: =#REF! -> #REF!
A135: REQ134 | C135: FR - Fungsional | D135: Must have | E135: BRD | F135: v1.0 | H135: =#REF! -> #REF! | J135: =#REF! -> #REF! | M135: UAT1 | N135: Not Run | U135: =#REF! -> #REF!
A136: REQ135 | C136: FR - Fungsional | D136: Must have | E136: BRD | F136: v1.0 | H136: =#REF! -> #REF! | J136: =#REF! -> #REF! | M136: UAT1 | N136: Not Run | U136: =#REF! -> #REF!

Sheet DASHBOARD
A1: Dashboard RTM - Otomatis
A3: Total Requirement | B3: Ter-mapping ke Test Case | C3: Mapping Coverage % | D3: Pass Rate % (Executed) | E3: Defect Open Critical/High | F3: Requirement tanpa Test Case
A4: =COUNTIF(RTM!$A$2:$A$995,"<>") -> 135 | B4: =COUNTIFS(RTM!$A$2:$A$995,"<>",RTM!$K$2:$K$995,"<>") -> 0 | C4: =IFERROR(B4/A4,0) -> 0 | D4: =IFERROR(D5/(D5+D6+D7),0) -> 0 | E4: =COUNTIFS(RTM!$P$2:$P$995,"<>",RTM!$Q$2:$Q$995,"Critical",RTM!$R$2:$R$995,"Open")+COUNTIFS(RTM!$P$2:$P$995,"<>",RTM!$Q$2:$Q$995,"Critical",RTM!$R$2:$R$995,"In Progress")+COUNTIFS(RTM!$P$2:$P$995,"<>",RTM!$Q$2:$Q$995,"High",RTM!$R$2:$R$995,"Open")+COUNTIFS(RTM!$P$2:$P$995,"<>",RTM!$Q$2:$Q$995,"High",RTM!$R$2:$R$995,"In Progress") -> 0 | F4: =COUNTIFS(RTM!$A$2:$A$995,"<>",RTM!$K$2:$K$995,"") -> 135
D5: =COUNTIFS(RTM!$A$2:$A$995,"<>",RTM!$N$2:$N$995,"Pass") -> 0
D6: =COUNTIFS(RTM!$A$2:$A$995,"<>",RTM!$N$2:$N$995,"Fail") -> 0
D7: =COUNTIFS(RTM!$A$2:$A$995,"<>",RTM!$N$2:$N$995,"Blocked") -> 0
A10: Ringkasan Coverage
A11: Status | B11: Jumlah
A12: Covered | B12: =COUNTIFS(RTM!$A$2:$A$995,"<>",RTM!$S$2:$S$995,"Covered") -> 0
A13: Partial | B13: =COUNTIFS(RTM!$A$2:$A$995,"<>",RTM!$S$2:$S$995,"Partial") -> 0
A14: Gap | B14: =COUNTIFS(RTM!$A$2:$A$995,"<>",RTM!$S$2:$S$995,"Gap") -> 0
A29: Ringkasan Status Pengujian
A30: Status | B30: Jumlah
A31: Pass | B31: =COUNTIFS(RTM!$A$2:$A$995,"<>",RTM!$N$2:$N$995,"Pass") -> 0
A32: Fail | B32: =COUNTIFS(RTM!$A$2:$A$995,"<>",RTM!$N$2:$N$995,"Fail") -> 0
A33: Blocked | B33: =COUNTIFS(RTM!$A$2:$A$995,"<>",RTM!$N$2:$N$995,"Blocked") -> 0
A34: Not Run | B34: =COUNTIFS(RTM!$A$2:$A$995,"<>",RTM!$N$2:$N$995,"Not Run") -> 135
A49: Defect berdasarkan Severity
A50: Severity | B50: Jumlah
A51: Critical | B51: =COUNTIFS(RTM!$P$2:$P$995,"<>",RTM!$Q$2:$Q$995,"Critical") -> 0
A52: High | B52: =COUNTIFS(RTM!$P$2:$P$995,"<>",RTM!$Q$2:$Q$995,"High") -> 0
A53: Medium | B53: =COUNTIFS(RTM!$P$2:$P$995,"<>",RTM!$Q$2:$Q$995,"Medium") -> 0
A54: Low | B54: =COUNTIFS(RTM!$P$2:$P$995,"<>",RTM!$Q$2:$Q$995,"Low") -> 0
A55: Trivial | B55: =COUNTIFS(RTM!$P$2:$P$995,"<>",RTM!$Q$2:$Q$995,"Trivial") -> 0
A57: Catatan: Semua metrik menggunakan rentang RTM baris 2–1000. Ubah jika diperlukan.
A69: KPI Gating SIT
A70: Kriteria | B70: Target | C70: Nilai Saat Ini | D70: Status
A71: Coverage ter-mapping ke Test Case | B71: >= 100% | C71: =C4 -> 0 | D71: =IF(C4>=1,"OK","Belum OK") -> Belum OK
A72: Pass Rate (executed) | B72: >= 95% | C72: =D4 -> 0 | D72: =IF(D4>=0.95,"OK","Belum OK") -> Belum OK
A73: Critical/High defect OPEN/IN PROGRESS | B73: =0 -> 0 | C73: =E4 -> 0 | D73: =IF(E4=0,"OK","Belum OK") -> OK
A74: Requirement tanpa Test Case | B74: =0 -> 0 | C74: =F4 -> 135 | D74: =IF(F4=0,"OK","Belum OK") -> Belum OK
A75: Keputusan SIT Exit | B75: Semua kriteria = OK | D75: =IF(COUNTIF(D71:D74,"OK")=ROWS(D71:D74),"GO","NO-GO") -> NO-GO
A78: KPI Gating UAT
A79: Kriteria | B79: Target | C79: Nilai Saat Ini | D79: Status
A80: Pass Rate (executed) | B80: >= 97% | C80: =D4 -> 0 | D80: =IF(D4>=0.97,"OK","Belum OK") -> Belum OK
